{
  "comments": [
    {
      "unresolved": false,
      "key": {
        "uuid": "488851c2_0f9280a6",
        "filename": "/PATCHSET_LEVEL",
        "patchSetId": 1
      },
      "lineNbr": 0,
      "author": {
        "id": 1054468
      },
      "writtenOn": "2021-09-30T20:12:33Z",
      "side": 1,
      "message": "Is the test failure related? \"Failed to parse the python logs: Parser finished in unexpected state TRACEBACK. Please ensure that verbosity of output is high enough to be parsed.\"\n\nIt doesn\u0027t seem to be, and the test does appear to be flaky. ",
      "revId": "58a73ad7cbe0f1a304c96438b147a5b715bd340c",
      "serverId": "85c56323-6fa9-3386-8a01-6480fb634889"
    }
  ]
}